<?xml version="1.0"?>
<robot xmlns:xacro="http://www.ros.org/wiki/xacro" >
<xacro:include filename="inertial_macros.xacro" />

    <material name="white">
        <color rgba="1 1 1 1" />
    </material>

    <material name="orange">
        <color rgba="1 0.5 0 1"/>
    </material>

    <material name="blue">
        <color rgba="0.2 0.6 1 1"/>
    </material>

    <material name="black">
        <color rgba="0 0 0 1"/>
    </material>

    <material name="red">
        <color rgba="1 0 0 1"/>
    </material>

<!-- BASE LINK -->
<link name="base_link">

</link>

<joint name="chassis_joint" type="fixed">
    <parent link="base_link"/>
    <child link="chassis"/>
    <origin xyz="0 0 0"/>
</joint>

<link name="chassis">
    <visual>
        <!-- <origin xyz="0 0 0" rpy="0 0 0"/> -->
        <geometry>
            <mesh filename="file://$(find articubot_one)/description/NewBody.dae" scale="10 10 10"/>
        </geometry>
        <material name="red"/>
    </visual>
    <collision>
          <!-- <origin xyz="0 0 0" rpy="0 0 0"/> -->
        <geometry>
         <mesh filename="file://$(find articubot_one)/description/NewBody.dae" scale="10 10 10"/>
        </geometry>
    </collision>
    <xacro:inertial_box mass="40" x="0.2" y="0.1" z="0.1">
        <origin xyz="0 0 0.05" rpy="0 0 0"/>
    </xacro:inertial_box>
</link>
<gazebo reference="chassis">
    <material>Gazebo/Orange</material>
</gazebo>

<!-- LEFT WHEEL back-->
<joint name= "left_wheel_back_joint" type="continuous">
    <parent link="base_link"/>
    <child link="left_wheel_back"/>
    <origin xyz=" -0.08 0.06 0" rpy="-${pi/2} 0 0"/>
    <axis xyz="0 0 1"/>
</joint>

<link name="left_wheel_back">
    <visual>
        <geometry>
            <cylinder length="0.02" radius="0.03" />
        </geometry>
        <material name="black"/>
    </visual>
    <collision>
        <geometry>
            <cylinder length="0.02" radius="0.03" />
        </geometry>
    </collision>
    <xacro:inertial_cylinder mass="6" length="0.02" radius="0.03">
        <origin xyz="0 0 0" rpy="0 0 0"/>
    </xacro:inertial_cylinder>
</link>
<gazebo reference="left_wheel_back">
    <material>Gazebo/Black</material>
    <mu1 value="0.8"/>
    <mu2 value="0.8"/>
</gazebo>

<!-- LEFT WHEEL FRONT-->
<joint name="left_wheel_front_joint" type="continuous">
    <parent link="base_link"/>
    <child link="left_wheel_front"/>
    <origin xyz=" 0.08 0.06 0" rpy="-${pi/2} 0 0"/>
    <axis xyz="0 0 1"/>
</joint>

<link name="left_wheel_front">
    <visual>
        <geometry>
            <cylinder length="0.02" radius="0.03" />
        </geometry>
        <material name="blue"/>
    </visual>
    <collision>
        <geometry>
            <cylinder length="0.02" radius="0.03" />
        </geometry>
    </collision>
    <xacro:inertial_cylinder mass="6" length="0.02" radius="0.03">
        <origin xyz="0 0 0" rpy="0 0 0"/>
    </xacro:inertial_cylinder>
</link>
<gazebo reference="left_wheel_front">
    <material>Gazebo/Blue</material>
    <mu1 value="0.8"/>
    <mu2 value="0.8"/>
</gazebo>

<!-- RIGHT WHEEL BACK-->

<joint name="right_wheel_back_joint" type="continuous">
    <parent link="base_link"/>
    <child link="right_wheel_back"/>
    <origin xyz="-0.08 -0.06 0" rpy=" ${pi/2} 0 0"/>
    <axis xyz="0 0 -1"/>
</joint>

<link name="right_wheel_back">
    <visual>
        <geometry>
            <cylinder length="0.02" radius="0.03" />
        </geometry>
        <material name="black"/>
    </visual>
    <collision>
        <geometry>
            <cylinder length="0.02" radius="0.03" />
        </geometry>
    </collision>
    <xacro:inertial_cylinder mass="6" length="0.02" radius="0.03">
        <origin xyz="0 0 0" rpy="0 0 0"/>
    </xacro:inertial_cylinder>
</link>
<gazebo reference="right_wheel_back">
    <material>Gazebo/Black</material>
    <mu1 value="0.8"/>
    <mu2 value="0.8"/>
</gazebo>

<!-- RIGHT WHEEL FRONT-->

<joint name="right_wheel_front_joint" type="continuous">
    <parent link="base_link"/>
    <child link="right_wheel_front"/>
    <origin xyz="0.08 -0.06 0" rpy="${pi/2} 0 0"/>
    <axis xyz="0 0 -1"/>
</joint>

<link name="right_wheel_front">
    <visual>
        <geometry>
            <cylinder length="0.02" radius="0.03" />
        </geometry>
        <material name="blue"/>
    </visual>
    <collision>
        <geometry>
            <cylinder length="0.02" radius="0.03" />
        </geometry>
    </collision>
    <xacro:inertial_cylinder mass="6" length="0.02" radius="0.03">
        <origin xyz="0 0 0" rpy="0 0 0"/>
    </xacro:inertial_cylinder>
</link>
<gazebo reference="right_wheel_front">
    <material>Gazebo/Blue</material>
    <mu1 value="0.8"/>
    <mu2 value="0.8"/>
</gazebo>

<!-- arm -->

<joint name="arm_joint" type="revolute">
    <parent link="chassis"/>
    <child link="arm"/>
    <origin xyz="0.1 0 0.1" rpy="0 0 0"/>
    <axis xyz="0 -1 0"/>
    <limit effort="100" velocity="10" lower="0" upper="${pi}"/> 
    <dynamics damping="1" friction="1"/> 
</joint>

<link name="arm">
    <visual>
        <origin xyz="0.015 0 -0.05" rpy="0 0 0"/> 
        <geometry>
            <box size="0.03 0.03 0.1"/>
        </geometry>
    </visual>
    <collision>
        <origin xyz="0.015 0 -0.05" rpy="0 0 0"/>
        <geometry>
            <box size="0.03 0.03 0.1"/>
        </geometry>
    </collision>
    <xacro:inertial_box mass="0.5" x="0.03" y="0.03" z="0.1">
        <origin xyz="0.015 0 -0.05" rpy="0 0 0"/>
    </xacro:inertial_box>
</link>
<gazebo reference="arm">
    <material>Gazebo/Red</material>
</gazebo>

<!-- Front_arm -->

<joint name= "front_arm_joint" type="revolute">
    <parent link="arm"/>
    <child link="front_arm_link"/>
    <origin xyz="0.03  0 -0.08" rpy="0 0 ${pi/2}"/>
    <axis xyz="1 0 0"/>
    <!-- <dynamics friction= "0.5" /> -->
    <limit effort= "100" velocity="5" lower="0" upper="${pi/3}"/> 
</joint>
<!-- <dynamics damping="0.01" friction="1"/> -->

<link name= "front_arm_link" >
      <visual>
        <origin xyz="0 0 -0.01" rpy="0 0 0"/> 
        <geometry>
            <!-- <box size="0.03 0.1 0.05"/> -->
            <mesh filename="file://$(find articubot_one)/description/handed2.dae" scale="5 5 5"/>
        </geometry>
    </visual>
    <collision>
        <origin xyz="0 0 -0.01" rpy="0 0 0"/>
        <geometry>
            <!-- <box size="0.03 0.1 0.05"/> -->
             <mesh filename="file://$(find articubot_one)/description/handed2.dae" scale="5 5 5"/>
        </geometry>
    </collision>
    <xacro:inertial_box mass="0.05" x="0.05" y="0.025" z="0.05">
        <origin xyz="0 0 -0.01" rpy="0 0 0"/>
    </xacro:inertial_box>
</link>
<gazebo reference="front_arm_link">
    <material>Gazebo/Red</material>
</gazebo>

</robot>